<robot name = "robot">
    <link name="Torso">
        <inertial>
            <origin xyz="1 0 1" rpy="0 0 0"/>
            <mass value="1" />
            <inertia ixx="100" ixy="0" ixz="0" iyy="100" iyz="0" izz="100" />
        </inertial>
        <visual>
            <origin xyz="1 0 1" rpy="0 0 0"/>
            <geometry>
                <box size="3 0.5 0.5" />
            </geometry>
            <material name="Cyan">
                <color rgba="0 1.0 1.0 1.0"/>
            </material>
        </visual>
        <collision>
            <origin xyz="1 0 1" rpy="0 0 0"/>
            <geometry>
                <box size="3 0.5 0.5" />
            </geometry>
        </collision>
    </link>
    <joint name="Torso_To_Front_Right" type="revolute">
       <parent link="Torso"/>
       <child  link="Front_Right_Leg"/>
       <origin rpy="0 0 0" xyz="0.125 0.25 1"/>
       <axis xyz="0 1 0"/>
       <limit effort="0.0" lower="-3.14159" upper="3.14159" velocity="0.0"/>
    </joint>
    <link name="Front_Right_Leg">
        <inertial>
            <origin xyz="0 0.125 -0.5" rpy="0 0 0"/>
            <mass value="1" />
            <inertia ixx="100" ixy="0" ixz="0" iyy="100" iyz="0" izz="100" />
        </inertial>
        <visual>
            <origin xyz="0 0.125 -0.5" rpy="0 0 0"/>
            <geometry>
                <box size="0.25 0.25 1" />
            </geometry>
            <material name="Cyan">
                <color rgba="0 1.0 1.0 1.0"/>
            </material>
        </visual>
        <collision>
            <origin xyz="0 0.125 -0.5" rpy="0 0 0"/>
            <geometry>
                <box size="0.25 0.25 1" />
            </geometry>
        </collision>
    </link>
    <joint name="Front_Right_To_Lower" type="revolute">
       <parent link="Front_Right_Leg"/>
       <child  link="Front_Right_Leg_Lower"/>
       <origin rpy="0 0 0" xyz="0 0.125 -1"/>
       <axis xyz="0 1 0"/>
       <limit effort="0.0" lower="-3.14159" upper="3.14159" velocity="0.0"/>
    </joint>
    <link name="Front_Right_Leg_Lower">
        <inertial>
            <origin xyz="-0.5 0.2 0" rpy="0 0 0"/>
            <mass value="1" />
            <inertia ixx="100" ixy="0" ixz="0" iyy="100" iyz="0" izz="100" />
        </inertial>
        <visual>
            <origin xyz="-0.5 0.2 0" rpy="0 0 0"/>
            <geometry>
                <box size="1 0.25 0.25" />
            </geometry>
            <material name="Cyan">
                <color rgba="0 1.0 1.0 1.0"/>
            </material>
        </visual>
        <collision>
            <origin xyz="-0.5 0.2 0" rpy="0 0 0"/>
            <geometry>
                <box size="1 0.25 0.25" />
            </geometry>
        </collision>
    </link>
    <joint name="Torso_To_Front_Left" type="revolute">
       <parent link="Torso"/>
       <child  link="Front_Left_Leg"/>
       <origin rpy="0 0 0" xyz="0.125 -0.25 1"/>
       <axis xyz="0 1 0"/>
       <limit effort="0.0" lower="-3.14159" upper="3.14159" velocity="0.0"/>
    </joint>
    <link name="Front_Left_Leg">
        <inertial>
            <origin xyz="0 -0.125 -0.5" rpy="0 0 0"/>
            <mass value="1" />
            <inertia ixx="100" ixy="0" ixz="0" iyy="100" iyz="0" izz="100" />
        </inertial>
        <visual>
            <origin xyz="0 -0.125 -0.5" rpy="0 0 0"/>
            <geometry>
                <box size="0.25 0.25 1" />
            </geometry>
            <material name="Cyan">
                <color rgba="0 1.0 1.0 1.0"/>
            </material>
        </visual>
        <collision>
            <origin xyz="0 -0.125 -0.5" rpy="0 0 0"/>
            <geometry>
                <box size="0.25 0.25 1" />
            </geometry>
        </collision>
    </link>
    <joint name="Front_Left_To_Lower" type="revolute">
       <parent link="Front_Left_Leg"/>
       <child  link="Front_Left_Leg_Lower"/>
       <origin rpy="0 0 0" xyz="0 -0.125 -1"/>
       <axis xyz="0 1 0"/>
       <limit effort="0.0" lower="-3.14159" upper="3.14159" velocity="0.0"/>
    </joint>
    <link name="Front_Left_Leg_Lower">
        <inertial>
            <origin xyz="-0.5 -0.2 0" rpy="0 0 0"/>
            <mass value="1" />
            <inertia ixx="100" ixy="0" ixz="0" iyy="100" iyz="0" izz="100" />
        </inertial>
        <visual>
            <origin xyz="-0.5 -0.2 0" rpy="0 0 0"/>
            <geometry>
                <box size="1 0.25 0.25" />
            </geometry>
            <material name="Cyan">
                <color rgba="0 1.0 1.0 1.0"/>
            </material>
        </visual>
        <collision>
            <origin xyz="-0.5 -0.2 0" rpy="0 0 0"/>
            <geometry>
                <box size="1 0.25 0.25" />
            </geometry>
        </collision>
    </link>
    <joint name="Torso_To_Back_Right" type="revolute">
       <parent link="Torso"/>
       <child  link="Back_Right_Leg"/>
       <origin rpy="0 0 0" xyz="2.25 0.25 1"/>
       <axis xyz="0 1 0"/>
       <limit effort="0.0" lower="-3.14159" upper="3.14159" velocity="0.0"/>
    </joint>
    <link name="Back_Right_Leg">
        <inertial>
            <origin xyz="0 0.125 -0.5" rpy="0 0 0"/>
            <mass value="1" />
            <inertia ixx="100" ixy="0" ixz="0" iyy="100" iyz="0" izz="100" />
        </inertial>
        <visual>
            <origin xyz="0 0.125 -0.5" rpy="0 0 0"/>
            <geometry>
                <box size="0.25 0.25 1" />
            </geometry>
            <material name="Cyan">
                <color rgba="0 1.0 1.0 1.0"/>
            </material>
        </visual>
        <collision>
            <origin xyz="0 0.125 -0.5" rpy="0 0 0"/>
            <geometry>
                <box size="0.25 0.25 1" />
            </geometry>
        </collision>
    </link>
    <joint name="Back_Right_To_Lower" type="revolute">
       <parent link="Back_Right_Leg"/>
       <child  link="Back_Right_Leg_Lower"/>
       <origin rpy="0 0 0" xyz="0 0.125 -1"/>
       <axis xyz="0 1 0"/>
       <limit effort="0.0" lower="-3.14159" upper="3.14159" velocity="0.0"/>
    </joint>
    <link name="Back_Right_Leg_Lower">
        <inertial>
            <origin xyz="-0.5 0.2 0" rpy="0 0 0"/>
            <mass value="1" />
            <inertia ixx="100" ixy="0" ixz="0" iyy="100" iyz="0" izz="100" />
        </inertial>
        <visual>
            <origin xyz="-0.5 0.2 0" rpy="0 0 0"/>
            <geometry>
                <box size="1 0.25 0.25" />
            </geometry>
            <material name="Cyan">
                <color rgba="0 1.0 1.0 1.0"/>
            </material>
        </visual>
        <collision>
            <origin xyz="-0.5 0.2 0" rpy="0 0 0"/>
            <geometry>
                <box size="1 0.25 0.25" />
            </geometry>
        </collision>
    </link>
    <joint name="Torso_To_Back_Left" type="revolute">
       <parent link="Torso"/>
       <child  link="Back_Left_Leg"/>
       <origin rpy="0 0 0" xyz="2.25 -0.25 1"/>
       <axis xyz="0 1 0"/>
       <limit effort="0.0" lower="-3.14159" upper="3.14159" velocity="0.0"/>
    </joint>
    <link name="Back_Left_Leg">
        <inertial>
            <origin xyz="0 -0.125 -0.5" rpy="0 0 0"/>
            <mass value="1" />
            <inertia ixx="100" ixy="0" ixz="0" iyy="100" iyz="0" izz="100" />
        </inertial>
        <visual>
            <origin xyz="0 -0.125 -0.5" rpy="0 0 0"/>
            <geometry>
                <box size="0.25 0.25 1" />
            </geometry>
            <material name="Cyan">
                <color rgba="0 1.0 1.0 1.0"/>
            </material>
        </visual>
        <collision>
            <origin xyz="0 -0.125 -0.5" rpy="0 0 0"/>
            <geometry>
                <box size="0.25 0.25 1" />
            </geometry>
        </collision>
    </link>
    <joint name="Back_Left_To_Lower" type="revolute">
       <parent link="Back_Left_Leg"/>
       <child  link="Back_Left_Leg_Lower"/>
       <origin rpy="0 0 0" xyz="0 -0.125 -1"/>
       <axis xyz="0 1 0"/>
       <limit effort="0.0" lower="-3.14159" upper="3.14159" velocity="0.0"/>
    </joint>
    <link name="Back_Left_Leg_Lower">
        <inertial>
            <origin xyz="-0.5 -0.2 0" rpy="0 0 0"/>
            <mass value="1" />
            <inertia ixx="100" ixy="0" ixz="0" iyy="100" iyz="0" izz="100" />
        </inertial>
        <visual>
            <origin xyz="-0.5 -0.2 0" rpy="0 0 0"/>
            <geometry>
                <box size="1 0.25 0.25" />
            </geometry>
            <material name="Cyan">
                <color rgba="0 1.0 1.0 1.0"/>
            </material>
        </visual>
        <collision>
            <origin xyz="-0.5 -0.2 0" rpy="0 0 0"/>
            <geometry>
                <box size="1 0.25 0.25" />
            </geometry>
        </collision>
    </link>
</robot>